<?xml version="1.0"?>
<robot name="arm">
    <material name="blue">
        <color rgba="0 0 0.8 1"/>
    </material>
    <material name="black">
        <color rgba="0 0 0 1"/>
    </material>
    <material name="white">
        <color rgba="1 1 1 1"/>
    </material>

    <link name="base_link">
    </link>

    <link name="base_plate">
        <visual>
            <origin xyz="0 0 0.05"/>
            <geometry>
                <cylinder radius="0.25" length="0.1"/>
            </geometry>
            <material name="black"/>
        </visual>
    </link>

    <link name="arm_link_1">
        <visual>
            <origin xyz="0 0 0.25"/>
            <geometry>
                <box size="0.1 0.1 0.5"/>
            </geometry>
            <material name="white"/>
        </visual>
    </link>

    <link name="arm_link_2">
        <visual>
            <origin xyz="0 0 0.25"/>
            <geometry>
                <box size="0.1 0.1 0.5"/>
            </geometry>
            <material name="blue"/>
        </visual>
    </link>

    <joint name="base_joint" type="fixed">
        <origin xyz="0 0 0"/>
        <parent link="base_link"/>
        <child link="base_plate"/>
    </joint>

    <joint name="arm_joint_1" type="revolute">
        <axis xyz="0 1 0"/>
        <limit effort="1000.0" lower="-1.5708" upper="1.5708" velocity="0.5"/>
        <origin rpy="0 0 0" xyz="0 0 0"/>
        <parent link="base_plate"/>
        <child link="arm_link_1"/>
    </joint>

    <joint name="arm_joint_2" type="revolute">
        <axis xyz="0 1 0"/>
        <limit effort="1000.0" lower="-1.5708" upper="1.5708" velocity="0.5"/>
        <origin rpy="0 0 0" xyz="0 0 0.5"/>
        <parent link="arm_link_1"/>
        <child link="arm_link_2"/>
    </joint>

</robot>